Traceback (most recent call last):
  File "/common/software/install/migrated/anaconda/python3-2020.07-mamba/lib/python3.8/runpy.py", line 194, in _run_module_as_main
    return _run_code(code, main_globals, None,
  File "/common/software/install/migrated/anaconda/python3-2020.07-mamba/lib/python3.8/runpy.py", line 87, in _run_code
    exec(code, run_globals)
  File "/panfs/jay/groups/28/yaoyi/pyo00005/CriticalMAAS/src/umn-ta2-mineral-site-linkage/minelink/__main__.py", line 42, in <module>
    main(parser.parse_args())
  File "/panfs/jay/groups/28/yaoyi/pyo00005/CriticalMAAS/src/umn-ta2-mineral-site-linkage/minelink/__main__.py", line 22, in main
    preprocessing(list_code, mss_code)
  File "/panfs/jay/groups/28/yaoyi/pyo00005/CriticalMAAS/src/umn-ta2-mineral-site-linkage/minelink/m1_input_preprocessing/preprocess_input.py", line 16, in preprocessing
    process_dataframe(i)
  File "/panfs/jay/groups/28/yaoyi/pyo00005/CriticalMAAS/src/umn-ta2-mineral-site-linkage/minelink/m1_input_preprocessing/preprocess_dataframe.py", line 115, in process_dataframe
    unique_id, col_name, latitude, longitude, crs, dict_text_loc, remaining_columns = identify_column(pl_data, dict_data)
  File "/panfs/jay/groups/28/yaoyi/pyo00005/CriticalMAAS/src/umn-ta2-mineral-site-linkage/minelink/m1_input_preprocessing/identify_columns.py", line 196, in identify_column
    latitude, longitude, crs = identify_geo_location(pl_data, remaining_columns, dict_data, dict_target)
  File "/panfs/jay/groups/28/yaoyi/pyo00005/CriticalMAAS/src/umn-ta2-mineral-site-linkage/minelink/m1_input_preprocessing/identify_columns.py", line 157, in identify_geo_location
    rep_latitude = col_latitude[0]
IndexError: list index out of range
[]
[] [] 
